01-17 12:49:10: INFO >> "GET / HTTP/1.1" 200 3955
01-17 12:49:10: WARNING >> Not Found: /favicon.ico
01-17 12:49:10: WARNING >> "GET /favicon.ico HTTP/1.1" 404 4890
01-17 12:49:16: INFO >> "GET /dj-auth/login/ HTTP/1.1" 200 3345
01-17 12:51:41: WARNING >> Not Found: /login
01-17 12:51:41: WARNING >> "POST /login HTTP/1.1" 404 4873
01-17 12:55:43: ERROR >> Internal Server Error: /log-api/
Traceback (most recent call last):
  File "C:\Users\PV\AppData\Local\Programs\Python\Python36-32\lib\site-packages\django\core\handlers\exception.py", line 41, in inner
    response = get_response(request)
  File "C:\Users\PV\AppData\Local\Programs\Python\Python36-32\lib\site-packages\django\core\handlers\base.py", line 187, in _get_response
    response = self.process_exception_by_middleware(e, request)
  File "C:\Users\PV\AppData\Local\Programs\Python\Python36-32\lib\site-packages\django\core\handlers\base.py", line 185, in _get_response
    response = wrapped_callback(request, *callback_args, **callback_kwargs)
  File "C:\Users\PV\AppData\Local\Programs\Python\Python36-32\lib\site-packages\django\views\decorators\csrf.py", line 58, in wrapped_view
    return view_func(*args, **kwargs)
  File "C:\Users\PV\AppData\Local\Programs\Python\Python36-32\lib\site-packages\django\views\generic\base.py", line 68, in view
    return self.dispatch(request, *args, **kwargs)
  File "C:\Users\PV\AppData\Local\Programs\Python\Python36-32\lib\site-packages\rest_framework\views.py", line 489, in dispatch
    response = self.handle_exception(exc)
  File "C:\Users\PV\AppData\Local\Programs\Python\Python36-32\lib\site-packages\rest_framework\views.py", line 449, in handle_exception
    self.raise_uncaught_exception(exc)
  File "C:\Users\PV\AppData\Local\Programs\Python\Python36-32\lib\site-packages\rest_framework\views.py", line 486, in dispatch
    response = handler(request, *args, **kwargs)
  File "D:\PV\My_work\splutsk\dev_build\api\accounts\views.py", line 53, in post
    serializer = self.serializer_class(data=user)
TypeError: 'tuple' object is not callable
01-17 12:55:44: ERROR >> "POST /log-api/ HTTP/1.1" 500 21223
01-17 12:56:38: ERROR >> Internal Server Error: /accounts/api-login/
Traceback (most recent call last):
  File "C:\Users\PV\AppData\Local\Programs\Python\Python36-32\lib\site-packages\django\core\handlers\exception.py", line 41, in inner
    response = get_response(request)
  File "C:\Users\PV\AppData\Local\Programs\Python\Python36-32\lib\site-packages\django\core\handlers\base.py", line 187, in _get_response
    response = self.process_exception_by_middleware(e, request)
  File "C:\Users\PV\AppData\Local\Programs\Python\Python36-32\lib\site-packages\django\core\handlers\base.py", line 185, in _get_response
    response = wrapped_callback(request, *callback_args, **callback_kwargs)
  File "C:\Users\PV\AppData\Local\Programs\Python\Python36-32\lib\site-packages\django\views\decorators\csrf.py", line 58, in wrapped_view
    return view_func(*args, **kwargs)
  File "C:\Users\PV\AppData\Local\Programs\Python\Python36-32\lib\site-packages\django\views\generic\base.py", line 68, in view
    return self.dispatch(request, *args, **kwargs)
  File "C:\Users\PV\AppData\Local\Programs\Python\Python36-32\lib\site-packages\rest_framework\views.py", line 489, in dispatch
    response = self.handle_exception(exc)
  File "C:\Users\PV\AppData\Local\Programs\Python\Python36-32\lib\site-packages\rest_framework\views.py", line 449, in handle_exception
    self.raise_uncaught_exception(exc)
  File "C:\Users\PV\AppData\Local\Programs\Python\Python36-32\lib\site-packages\rest_framework\views.py", line 486, in dispatch
    response = handler(request, *args, **kwargs)
  File "D:\PV\My_work\splutsk\dev_build\api\accounts\views.py", line 53, in post
    serializer = self.serializer_class(data=user)
TypeError: 'tuple' object is not callable
01-17 12:56:38: ERROR >> "POST /accounts/api-login/ HTTP/1.1" 500 21267
01-17 14:01:24: ERROR >> Internal Server Error: /accounts/api-login/
Traceback (most recent call last):
  File "C:\Users\PV\AppData\Local\Programs\Python\Python36-32\lib\site-packages\django\core\handlers\exception.py", line 41, in inner
    response = get_response(request)
  File "C:\Users\PV\AppData\Local\Programs\Python\Python36-32\lib\site-packages\django\core\handlers\base.py", line 187, in _get_response
    response = self.process_exception_by_middleware(e, request)
  File "C:\Users\PV\AppData\Local\Programs\Python\Python36-32\lib\site-packages\django\core\handlers\base.py", line 185, in _get_response
    response = wrapped_callback(request, *callback_args, **callback_kwargs)
  File "C:\Users\PV\AppData\Local\Programs\Python\Python36-32\lib\site-packages\django\views\decorators\csrf.py", line 58, in wrapped_view
    return view_func(*args, **kwargs)
  File "C:\Users\PV\AppData\Local\Programs\Python\Python36-32\lib\site-packages\django\views\generic\base.py", line 68, in view
    return self.dispatch(request, *args, **kwargs)
  File "C:\Users\PV\AppData\Local\Programs\Python\Python36-32\lib\site-packages\rest_framework\views.py", line 489, in dispatch
    response = self.handle_exception(exc)
  File "C:\Users\PV\AppData\Local\Programs\Python\Python36-32\lib\site-packages\rest_framework\views.py", line 449, in handle_exception
    self.raise_uncaught_exception(exc)
  File "C:\Users\PV\AppData\Local\Programs\Python\Python36-32\lib\site-packages\rest_framework\views.py", line 486, in dispatch
    response = handler(request, *args, **kwargs)
  File "D:\PV\My_work\splutsk\dev_build\api\accounts\views.py", line 53, in post
    serializer = self.serializer_class(data=user)
TypeError: 'tuple' object is not callable
01-17 14:01:24: ERROR >> "POST /accounts/api-login/ HTTP/1.1" 500 21267
01-17 14:08:18: INFO >> User with email: "test_p8@mail.com" and name: "P8c" was created successful.
01-17 14:08:20: INFO >> "POST /accounts/register/ HTTP/1.1" 201 319
01-17 14:09:26: WARNING >> Not Found: /api/list-users/
01-17 14:09:26: WARNING >> "GET /api/list-users/ HTTP/1.1" 404 4902
01-17 14:09:48: INFO >> "GET /accounts/api/list-users/ HTTP/1.1" 200 914
01-17 14:10:50: WARNING >> Not Found: /accounts/api/
01-17 14:10:50: WARNING >> "GET /accounts/api/?=pvpasha@meta.ua/ HTTP/1.1" 404 5771
01-17 14:10:54: WARNING >> Not Found: /accounts/api/
01-17 14:10:54: WARNING >> "GET /accounts/api/?pvpasha@meta.ua/ HTTP/1.1" 404 5770
01-17 14:10:59: WARNING >> "GET /accounts/api/pvpasha@meta.ua/ HTTP/1.1" 401 58
01-17 14:12:51: ERROR >> Internal Server Error: /accounts/api-login/
Traceback (most recent call last):
  File "C:\Users\PV\AppData\Local\Programs\Python\Python36-32\lib\site-packages\django\core\handlers\exception.py", line 41, in inner
    response = get_response(request)
  File "C:\Users\PV\AppData\Local\Programs\Python\Python36-32\lib\site-packages\django\core\handlers\base.py", line 187, in _get_response
    response = self.process_exception_by_middleware(e, request)
  File "C:\Users\PV\AppData\Local\Programs\Python\Python36-32\lib\site-packages\django\core\handlers\base.py", line 185, in _get_response
    response = wrapped_callback(request, *callback_args, **callback_kwargs)
  File "C:\Users\PV\AppData\Local\Programs\Python\Python36-32\lib\site-packages\django\views\decorators\csrf.py", line 58, in wrapped_view
    return view_func(*args, **kwargs)
  File "C:\Users\PV\AppData\Local\Programs\Python\Python36-32\lib\site-packages\django\views\generic\base.py", line 68, in view
    return self.dispatch(request, *args, **kwargs)
  File "C:\Users\PV\AppData\Local\Programs\Python\Python36-32\lib\site-packages\rest_framework\views.py", line 489, in dispatch
    response = self.handle_exception(exc)
  File "C:\Users\PV\AppData\Local\Programs\Python\Python36-32\lib\site-packages\rest_framework\views.py", line 449, in handle_exception
    self.raise_uncaught_exception(exc)
  File "C:\Users\PV\AppData\Local\Programs\Python\Python36-32\lib\site-packages\rest_framework\views.py", line 486, in dispatch
    response = handler(request, *args, **kwargs)
  File "D:\PV\My_work\splutsk\dev_build\api\accounts\views.py", line 53, in post
    serializer = self.serializer_class(data=user)
TypeError: 'tuple' object is not callable
01-17 14:12:51: ERROR >> "POST /accounts/api-login/ HTTP/1.1" 500 21267
01-17 16:40:26: INFO >> "POST /dj-auth/login/ HTTP/1.1" 302 0
01-17 16:40:27: INFO >> "GET / HTTP/1.1" 200 4222
01-17 16:40:27: INFO >> "GET /media/cache/5d/ed/5dedfceb2ec4c7dcdeb5d927a659a2af.jpg HTTP/1.1" 200 2115
01-17 16:40:27: INFO >> "GET /media/cache/62/5e/625e6c0a260c80bebf45ff6b446025d5.jpg HTTP/1.1" 200 4241
01-17 16:40:34: INFO >> "GET /dj-auth/logout/ HTTP/1.1" 200 272
01-17 16:40:36: INFO >> "GET / HTTP/1.1" 200 3955
01-17 16:43:06: ERROR >> Internal Server Error: /log-api/
Traceback (most recent call last):
  File "C:\Users\PV\AppData\Local\Programs\Python\Python36-32\lib\site-packages\django\core\handlers\exception.py", line 41, in inner
    response = get_response(request)
  File "C:\Users\PV\AppData\Local\Programs\Python\Python36-32\lib\site-packages\django\core\handlers\base.py", line 187, in _get_response
    response = self.process_exception_by_middleware(e, request)
  File "C:\Users\PV\AppData\Local\Programs\Python\Python36-32\lib\site-packages\django\core\handlers\base.py", line 185, in _get_response
    response = wrapped_callback(request, *callback_args, **callback_kwargs)
  File "C:\Users\PV\AppData\Local\Programs\Python\Python36-32\lib\site-packages\django\views\decorators\csrf.py", line 58, in wrapped_view
    return view_func(*args, **kwargs)
  File "C:\Users\PV\AppData\Local\Programs\Python\Python36-32\lib\site-packages\django\views\generic\base.py", line 68, in view
    return self.dispatch(request, *args, **kwargs)
  File "C:\Users\PV\AppData\Local\Programs\Python\Python36-32\lib\site-packages\rest_framework\views.py", line 489, in dispatch
    response = self.handle_exception(exc)
  File "C:\Users\PV\AppData\Local\Programs\Python\Python36-32\lib\site-packages\rest_framework\views.py", line 449, in handle_exception
    self.raise_uncaught_exception(exc)
  File "C:\Users\PV\AppData\Local\Programs\Python\Python36-32\lib\site-packages\rest_framework\views.py", line 486, in dispatch
    response = handler(request, *args, **kwargs)
  File "D:\PV\My_work\splutsk\dev_build\api\accounts\views.py", line 53, in post
    serializer = self.serializer_class(data=user)
TypeError: 'tuple' object is not callable
01-17 16:43:06: ERROR >> "POST /log-api/ HTTP/1.1" 500 21223
01-17 17:32:24: INFO >> "GET / HTTP/1.1" 200 3955
01-17 18:28:04: ERROR >> Internal Server Error: /log-api/
Traceback (most recent call last):
  File "D:\PV\My_work\splutsk\dev_build\venv\lib\site-packages\django\core\handlers\exception.py", line 41, in inner
    response = get_response(request)
  File "D:\PV\My_work\splutsk\dev_build\venv\lib\site-packages\django\core\handlers\base.py", line 187, in _get_response
    response = self.process_exception_by_middleware(e, request)
  File "D:\PV\My_work\splutsk\dev_build\venv\lib\site-packages\django\core\handlers\base.py", line 185, in _get_response
    response = wrapped_callback(request, *callback_args, **callback_kwargs)
  File "D:\PV\My_work\splutsk\dev_build\venv\lib\site-packages\django\views\decorators\csrf.py", line 58, in wrapped_view
    return view_func(*args, **kwargs)
  File "D:\PV\My_work\splutsk\dev_build\venv\lib\site-packages\django\views\generic\base.py", line 68, in view
    return self.dispatch(request, *args, **kwargs)
  File "D:\PV\My_work\splutsk\dev_build\venv\lib\site-packages\rest_framework\views.py", line 489, in dispatch
    response = self.handle_exception(exc)
  File "D:\PV\My_work\splutsk\dev_build\venv\lib\site-packages\rest_framework\views.py", line 449, in handle_exception
    self.raise_uncaught_exception(exc)
  File "D:\PV\My_work\splutsk\dev_build\venv\lib\site-packages\rest_framework\views.py", line 486, in dispatch
    response = handler(request, *args, **kwargs)
  File "D:\PV\My_work\splutsk\dev_build\api\accounts\views.py", line 53, in post
    serializer = self.serializer_class(data=user)
TypeError: 'tuple' object is not callable
01-17 18:28:05: ERROR >> "POST /log-api/ HTTP/1.1" 500 22261
01-17 18:28:37: ERROR >> Internal Server Error: /log-api/
Traceback (most recent call last):
  File "D:\PV\My_work\splutsk\dev_build\venv\lib\site-packages\django\core\handlers\exception.py", line 41, in inner
    response = get_response(request)
  File "D:\PV\My_work\splutsk\dev_build\venv\lib\site-packages\django\core\handlers\base.py", line 187, in _get_response
    response = self.process_exception_by_middleware(e, request)
  File "D:\PV\My_work\splutsk\dev_build\venv\lib\site-packages\django\core\handlers\base.py", line 185, in _get_response
    response = wrapped_callback(request, *callback_args, **callback_kwargs)
  File "D:\PV\My_work\splutsk\dev_build\venv\lib\site-packages\django\views\decorators\csrf.py", line 58, in wrapped_view
    return view_func(*args, **kwargs)
  File "D:\PV\My_work\splutsk\dev_build\venv\lib\site-packages\django\views\generic\base.py", line 68, in view
    return self.dispatch(request, *args, **kwargs)
  File "D:\PV\My_work\splutsk\dev_build\venv\lib\site-packages\rest_framework\views.py", line 489, in dispatch
    response = self.handle_exception(exc)
  File "D:\PV\My_work\splutsk\dev_build\venv\lib\site-packages\rest_framework\views.py", line 449, in handle_exception
    self.raise_uncaught_exception(exc)
  File "D:\PV\My_work\splutsk\dev_build\venv\lib\site-packages\rest_framework\views.py", line 486, in dispatch
    response = handler(request, *args, **kwargs)
  File "D:\PV\My_work\splutsk\dev_build\api\accounts\views.py", line 53, in post
    serializer = self.serializer_class(data=user)
TypeError: 'tuple' object is not callable
01-17 18:28:37: ERROR >> "POST /log-api/ HTTP/1.1" 500 22261
01-17 19:05:35: INFO >> Token for user with email: "<BoundField value=pvpasha@meta.ua errors=None>" was save
01-17 19:05:37: INFO >> "POST /api-token-auth/ HTTP/1.1" 200 236
01-17 19:20:09: INFO >> "OPTIONS /api-token-auth/ HTTP/1.1" 200 498
01-17 19:21:53: INFO >> Token for user with email: "<BoundField value=pvpasha@meta.ua errors=None>" was save
01-17 19:21:55: INFO >> "POST /api-token-auth/ HTTP/1.1" 200 236
01-17 19:24:59: ERROR >> Internal Server Error: /api-token-auth/
Traceback (most recent call last):
  File "D:\PV\My_work\splutsk\dev_build\venv\lib\site-packages\django\core\handlers\exception.py", line 41, in inner
    response = get_response(request)
  File "D:\PV\My_work\splutsk\dev_build\venv\lib\site-packages\django\core\handlers\base.py", line 187, in _get_response
    response = self.process_exception_by_middleware(e, request)
  File "D:\PV\My_work\splutsk\dev_build\venv\lib\site-packages\django\core\handlers\base.py", line 185, in _get_response
    response = wrapped_callback(request, *callback_args, **callback_kwargs)
  File "D:\PV\My_work\splutsk\dev_build\venv\lib\site-packages\django\views\decorators\csrf.py", line 58, in wrapped_view
    return view_func(*args, **kwargs)
  File "D:\PV\My_work\splutsk\dev_build\venv\lib\site-packages\django\views\generic\base.py", line 68, in view
    return self.dispatch(request, *args, **kwargs)
  File "D:\PV\My_work\splutsk\dev_build\venv\lib\site-packages\rest_framework\views.py", line 489, in dispatch
    response = self.handle_exception(exc)
  File "D:\PV\My_work\splutsk\dev_build\venv\lib\site-packages\rest_framework\views.py", line 449, in handle_exception
    self.raise_uncaught_exception(exc)
  File "D:\PV\My_work\splutsk\dev_build\venv\lib\site-packages\rest_framework\views.py", line 486, in dispatch
    response = handler(request, *args, **kwargs)
  File "D:\PV\My_work\splutsk\dev_build\venv\lib\site-packages\rest_framework_jwt\views.py", line 60, in post
    response_data = jwt_response_payload_handler(token, user, request)
  File "D:\PV\My_work\splutsk\dev_build\api\accounts\views.py", line 139, in jwt_response_handler_user
    logger.info(msg='Token for user with email: "%s" was save' % organizer_user_item['email'])
TypeError: 'OrganizerUser' object is not subscriptable
01-17 19:24:59: ERROR >> "POST /api-token-auth/ HTTP/1.1" 500 22566
01-17 19:26:04: ERROR >> Internal Server Error: /api-token-auth/
Traceback (most recent call last):
  File "D:\PV\My_work\splutsk\dev_build\venv\lib\site-packages\django\core\handlers\exception.py", line 41, in inner
    response = get_response(request)
  File "D:\PV\My_work\splutsk\dev_build\venv\lib\site-packages\django\core\handlers\base.py", line 187, in _get_response
    response = self.process_exception_by_middleware(e, request)
  File "D:\PV\My_work\splutsk\dev_build\venv\lib\site-packages\django\core\handlers\base.py", line 185, in _get_response
    response = wrapped_callback(request, *callback_args, **callback_kwargs)
  File "D:\PV\My_work\splutsk\dev_build\venv\lib\site-packages\django\views\decorators\csrf.py", line 58, in wrapped_view
    return view_func(*args, **kwargs)
  File "D:\PV\My_work\splutsk\dev_build\venv\lib\site-packages\django\views\generic\base.py", line 68, in view
    return self.dispatch(request, *args, **kwargs)
  File "D:\PV\My_work\splutsk\dev_build\venv\lib\site-packages\rest_framework\views.py", line 489, in dispatch
    response = self.handle_exception(exc)
  File "D:\PV\My_work\splutsk\dev_build\venv\lib\site-packages\rest_framework\views.py", line 449, in handle_exception
    self.raise_uncaught_exception(exc)
  File "D:\PV\My_work\splutsk\dev_build\venv\lib\site-packages\rest_framework\views.py", line 486, in dispatch
    response = handler(request, *args, **kwargs)
  File "D:\PV\My_work\splutsk\dev_build\venv\lib\site-packages\rest_framework_jwt\views.py", line 60, in post
    response_data = jwt_response_payload_handler(token, user, request)
  File "D:\PV\My_work\splutsk\dev_build\api\accounts\views.py", line 139, in jwt_response_handler_user
    logger.info(msg='Token for user with email: "%s" was save' % organizer_user_serializer['email'])
TypeError: 'OrganizerUser' object is not subscriptable
01-17 19:26:04: ERROR >> "POST /api-token-auth/ HTTP/1.1" 500 22572
01-17 19:26:18: INFO >> Token for user with email: "<BoundField value=pvpasha@meta.ua errors=None>" was save
01-17 19:26:20: INFO >> "POST /api-token-auth/ HTTP/1.1" 200 236
01-17 19:27:24: INFO >> Token for user with email "<BoundField value=pvpasha@meta.ua errors=None>" was save
01-17 19:27:25: INFO >> "POST /api-token-auth/ HTTP/1.1" 200 236
01-17 19:28:21: INFO >> Token for user with email <BoundField value=pvpasha@meta.ua errors=None> was save
01-17 19:28:23: INFO >> "POST /api-token-auth/ HTTP/1.1" 200 236
01-17 19:28:42: WARNING >> "POST /api-token-auth/ HTTP/1.1" 400 57
01-17 19:29:32: WARNING >> "POST /api-token-auth/ HTTP/1.1" 400 57
01-17 19:32:03: INFO >> "OPTIONS /api-token-auth/ HTTP/1.1" 200 498
01-17 20:24:22: INFO >> Token for user with email <BoundField value=pvpasha@meta.ua errors=None> was save
01-17 20:24:23: INFO >> "POST /api-token-auth/ HTTP/1.1" 200 236
01-17 20:25:44: INFO >> "OPTIONS /api-token-auth/ HTTP/1.1" 200 498
01-17 20:25:48: INFO >> "OPTIONS /api-token-auth/ HTTP/1.1" 200 498
01-17 20:28:02: INFO >> "OPTIONS /api-token-auth/ HTTP/1.1" 200 498
01-17 20:28:37: INFO >> "OPTIONS /api-token-auth/ HTTP/1.1" 200 498
01-17 20:31:41: INFO >> "OPTIONS /api-token-auth/ HTTP/1.1" 200 498
01-17 20:35:35: WARNING >> "POST /api-token-auth/ HTTP/1.1" 415 62
01-17 20:35:42: INFO >> Token for user with email <BoundField value=pvpasha@meta.ua errors=None> was save
01-17 20:35:44: INFO >> "POST /api-token-auth/ HTTP/1.1" 200 236
01-17 20:36:17: INFO >> "OPTIONS /api-token-auth/ HTTP/1.1" 200 498
01-17 20:36:21: INFO >> "OPTIONS /api-token-auth/ HTTP/1.1" 200 498
01-17 20:50:25: INFO >> "OPTIONS /api-token-auth/ HTTP/1.1" 200 498
01-17 20:54:03: INFO >> Token for user with email <BoundField value=pvpasha@meta.ua errors=None> was save
01-17 20:54:04: INFO >> "POST /api-token-auth/ HTTP/1.1" 200 236
01-17 20:54:50: INFO >> "OPTIONS /api-token-auth/ HTTP/1.1" 200 498
01-17 21:14:21: INFO >> "OPTIONS /api-token-auth/ HTTP/1.1" 200 498
01-17 21:15:34: INFO >> "OPTIONS /api-token-auth/ HTTP/1.1" 200 498
01-17 21:17:11: ERROR >> Invalid HTTP_HOST header: 'localhost:8000'. You may need to add 'localhost' to ALLOWED_HOSTS.
01-17 21:17:11: WARNING >> "OPTIONS /api-token-auth/ HTTP/1.1" 400 75489
01-17 21:27:28: ERROR >> Invalid HTTP_HOST header: 'localhost:8000'. You may need to add 'localhost' to ALLOWED_HOSTS.
01-17 21:27:28: WARNING >> "OPTIONS /api-token-auth/ HTTP/1.1" 400 75489
01-17 22:11:19: INFO >> "OPTIONS /api-token-auth/ HTTP/1.1" 200 498
01-17 22:13:26: INFO >> Token for user with email <BoundField value=pvpasha@meta.ua errors=None> was save
01-17 22:13:28: INFO >> "POST /api-token-auth/ HTTP/1.1" 200 236
01-17 22:14:01: INFO >> Token for user with email <BoundField value=pvpasha@meta.ua errors=None> was save
01-17 22:14:02: INFO >> "POST /api-token-auth/ HTTP/1.1" 200 236
01-17 22:16:07: WARNING >> "POST /api-token-auth/ HTTP/1.1" 415 62
01-17 22:16:55: INFO >> Token for user with email <BoundField value=pvpasha@meta.ua errors=None> was save
01-17 22:16:56: INFO >> "POST /api-token-auth/ HTTP/1.1" 200 236
01/17 22:18:36: INFO >> Token for user with email <BoundField value=pvpasha@meta.ua errors=None> was save
01/17 22:18:37: INFO >> "POST /api-token-auth/ HTTP/1.1" 200 236
01/17 22:31:16: INFO >> Token for user with email <BoundField value=pvpasha@meta.ua errors=None> was save
01/17 22:31:17: INFO >> "POST /api-token-auth/ HTTP/1.1" 200 236
01/17 22:32:07: INFO >> "OPTIONS /api-token-auth/ HTTP/1.1" 200 498
01/17 22:32:30: INFO >> "OPTIONS /api-token-auth/ HTTP/1.1" 200 498
01/17 22:32:35: INFO >> "OPTIONS /api-token-auth/ HTTP/1.1" 200 498
01/17 22:32:48: INFO >> "OPTIONS /api-token-auth/ HTTP/1.1" 200 498
01/17 23:01:26: INFO >> Token for user with email <BoundField value=pvpasha@meta.ua errors=None> was save
01/17 23:01:27: ERROR >> Internal Server Error: /api-token-auth/
Traceback (most recent call last):
  File "D:\PV\My_work\splutsk\dev_build\venv\lib\site-packages\django\core\handlers\exception.py", line 41, in inner
    response = get_response(request)
  File "D:\PV\My_work\splutsk\dev_build\venv\lib\site-packages\django\core\handlers\base.py", line 187, in _get_response
    response = self.process_exception_by_middleware(e, request)
  File "D:\PV\My_work\splutsk\dev_build\venv\lib\site-packages\django\core\handlers\base.py", line 185, in _get_response
    response = wrapped_callback(request, *callback_args, **callback_kwargs)
  File "D:\PV\My_work\splutsk\dev_build\venv\lib\site-packages\django\views\decorators\csrf.py", line 58, in wrapped_view
    return view_func(*args, **kwargs)
  File "D:\PV\My_work\splutsk\dev_build\venv\lib\site-packages\django\views\generic\base.py", line 68, in view
    return self.dispatch(request, *args, **kwargs)
  File "D:\PV\My_work\splutsk\dev_build\venv\lib\site-packages\rest_framework\views.py", line 489, in dispatch
    response = self.handle_exception(exc)
  File "D:\PV\My_work\splutsk\dev_build\venv\lib\site-packages\rest_framework\views.py", line 449, in handle_exception
    self.raise_uncaught_exception(exc)
  File "D:\PV\My_work\splutsk\dev_build\venv\lib\site-packages\rest_framework\views.py", line 486, in dispatch
    response = handler(request, *args, **kwargs)
  File "D:\PV\My_work\splutsk\dev_build\venv\lib\site-packages\rest_framework_jwt\views.py", line 60, in post
    response_data = jwt_response_payload_handler(token, user, request)
  File "D:\PV\My_work\splutsk\dev_build\api\accounts\views.py", line 143, in jwt_response_handler_user
    content_type='application/json'
  File "D:\PV\My_work\splutsk\dev_build\venv\lib\site-packages\rest_framework\response.py", line 48, in __init__
    for name, value in six.iteritems(headers):
  File "D:\PV\My_work\splutsk\dev_build\venv\lib\site-packages\django\utils\six.py", line 581, in iteritems
    return iter(d.items(**kw))
AttributeError: 'tuple' object has no attribute 'items'
01/17 23:01:27: ERROR >> "POST /api-token-auth/ HTTP/1.1" 500 22814
01/17 23:02:52: INFO >> Token for user with email <BoundField value=pvpasha@meta.ua errors=None> was save
01/17 23:02:53: ERROR >> Internal Server Error: /api-token-auth/
Traceback (most recent call last):
  File "D:\PV\My_work\splutsk\dev_build\venv\lib\site-packages\django\core\handlers\exception.py", line 41, in inner
    response = get_response(request)
  File "D:\PV\My_work\splutsk\dev_build\venv\lib\site-packages\django\core\handlers\base.py", line 187, in _get_response
    response = self.process_exception_by_middleware(e, request)
  File "D:\PV\My_work\splutsk\dev_build\venv\lib\site-packages\django\core\handlers\base.py", line 185, in _get_response
    response = wrapped_callback(request, *callback_args, **callback_kwargs)
  File "D:\PV\My_work\splutsk\dev_build\venv\lib\site-packages\django\views\decorators\csrf.py", line 58, in wrapped_view
    return view_func(*args, **kwargs)
  File "D:\PV\My_work\splutsk\dev_build\venv\lib\site-packages\django\views\generic\base.py", line 68, in view
    return self.dispatch(request, *args, **kwargs)
  File "D:\PV\My_work\splutsk\dev_build\venv\lib\site-packages\rest_framework\views.py", line 489, in dispatch
    response = self.handle_exception(exc)
  File "D:\PV\My_work\splutsk\dev_build\venv\lib\site-packages\rest_framework\views.py", line 449, in handle_exception
    self.raise_uncaught_exception(exc)
  File "D:\PV\My_work\splutsk\dev_build\venv\lib\site-packages\rest_framework\views.py", line 486, in dispatch
    response = handler(request, *args, **kwargs)
  File "D:\PV\My_work\splutsk\dev_build\venv\lib\site-packages\rest_framework_jwt\views.py", line 60, in post
    response_data = jwt_response_payload_handler(token, user, request)
  File "D:\PV\My_work\splutsk\dev_build\api\accounts\views.py", line 143, in jwt_response_handler_user
    content_type='application/json'
  File "D:\PV\My_work\splutsk\dev_build\venv\lib\site-packages\rest_framework\response.py", line 48, in __init__
    for name, value in six.iteritems(headers):
  File "D:\PV\My_work\splutsk\dev_build\venv\lib\site-packages\django\utils\six.py", line 581, in iteritems
    return iter(d.items(**kw))
AttributeError: 'set' object has no attribute 'items'
01/17 23:02:53: ERROR >> "POST /api-token-auth/ HTTP/1.1" 500 22810
01/17 23:03:28: INFO >> Token for user with email <BoundField value=pvpasha@meta.ua errors=None> was save
01/17 23:03:29: ERROR >> Internal Server Error: /api-token-auth/
Traceback (most recent call last):
  File "D:\PV\My_work\splutsk\dev_build\venv\lib\site-packages\django\core\handlers\exception.py", line 41, in inner
    response = get_response(request)
  File "D:\PV\My_work\splutsk\dev_build\venv\lib\site-packages\django\core\handlers\base.py", line 217, in _get_response
    response = self.process_exception_by_middleware(e, request)
  File "D:\PV\My_work\splutsk\dev_build\venv\lib\site-packages\django\core\handlers\base.py", line 215, in _get_response
    response = response.render()
  File "D:\PV\My_work\splutsk\dev_build\venv\lib\site-packages\django\template\response.py", line 107, in render
    self.content = self.rendered_content
  File "D:\PV\My_work\splutsk\dev_build\venv\lib\site-packages\rest_framework\response.py", line 72, in rendered_content
    ret = renderer.render(self.data, accepted_media_type, context)
  File "D:\PV\My_work\splutsk\dev_build\venv\lib\site-packages\rest_framework\renderers.py", line 105, in render
    allow_nan=not self.strict, separators=separators
  File "D:\PV\My_work\splutsk\dev_build\venv\lib\site-packages\rest_framework\utils\json.py", line 28, in dumps
    return json.dumps(*args, **kwargs)
  File "C:\Users\PV\AppData\Local\Programs\Python\Python36-32\lib\json\__init__.py", line 238, in dumps
    **kw).encode(obj)
  File "C:\Users\PV\AppData\Local\Programs\Python\Python36-32\lib\json\encoder.py", line 199, in encode
    chunks = self.iterencode(o, _one_shot=True)
  File "C:\Users\PV\AppData\Local\Programs\Python\Python36-32\lib\json\encoder.py", line 257, in iterencode
    return _iterencode(o, 0)
  File "D:\PV\My_work\splutsk\dev_build\venv\lib\site-packages\rest_framework\utils\encoders.py", line 68, in default
    return super(JSONEncoder, self).default(obj)
  File "C:\Users\PV\AppData\Local\Programs\Python\Python36-32\lib\json\encoder.py", line 180, in default
    o.__class__.__name__)
TypeError: Object of type 'Response' is not JSON serializable
01/17 23:03:29: ERROR >> "POST /api-token-auth/ HTTP/1.1" 500 111034
01/17 23:04:16: INFO >> Token for user with email <BoundField value=pvpasha@meta.ua errors=None> was save
01/17 23:04:17: ERROR >> Internal Server Error: /api-token-auth/
Traceback (most recent call last):
  File "D:\PV\My_work\splutsk\dev_build\venv\lib\site-packages\django\core\handlers\exception.py", line 41, in inner
    response = get_response(request)
  File "D:\PV\My_work\splutsk\dev_build\venv\lib\site-packages\django\core\handlers\base.py", line 217, in _get_response
    response = self.process_exception_by_middleware(e, request)
  File "D:\PV\My_work\splutsk\dev_build\venv\lib\site-packages\django\core\handlers\base.py", line 215, in _get_response
    response = response.render()
  File "D:\PV\My_work\splutsk\dev_build\venv\lib\site-packages\django\template\response.py", line 107, in render
    self.content = self.rendered_content
  File "D:\PV\My_work\splutsk\dev_build\venv\lib\site-packages\rest_framework\response.py", line 72, in rendered_content
    ret = renderer.render(self.data, accepted_media_type, context)
  File "D:\PV\My_work\splutsk\dev_build\venv\lib\site-packages\rest_framework\renderers.py", line 105, in render
    allow_nan=not self.strict, separators=separators
  File "D:\PV\My_work\splutsk\dev_build\venv\lib\site-packages\rest_framework\utils\json.py", line 28, in dumps
    return json.dumps(*args, **kwargs)
  File "C:\Users\PV\AppData\Local\Programs\Python\Python36-32\lib\json\__init__.py", line 238, in dumps
    **kw).encode(obj)
  File "C:\Users\PV\AppData\Local\Programs\Python\Python36-32\lib\json\encoder.py", line 199, in encode
    chunks = self.iterencode(o, _one_shot=True)
  File "C:\Users\PV\AppData\Local\Programs\Python\Python36-32\lib\json\encoder.py", line 257, in iterencode
    return _iterencode(o, 0)
  File "D:\PV\My_work\splutsk\dev_build\venv\lib\site-packages\rest_framework\utils\encoders.py", line 68, in default
    return super(JSONEncoder, self).default(obj)
  File "C:\Users\PV\AppData\Local\Programs\Python\Python36-32\lib\json\encoder.py", line 180, in default
    o.__class__.__name__)
TypeError: Object of type 'Response' is not JSON serializable
01/17 23:04:17: ERROR >> "POST /api-token-auth/ HTTP/1.1" 500 111034
01/17 23:06:43: INFO >> Token for user with email <BoundField value=pvpasha@meta.ua errors=None> was save
01/17 23:06:45: ERROR >> Internal Server Error: /api-token-auth/
Traceback (most recent call last):
  File "D:\PV\My_work\splutsk\dev_build\venv\lib\site-packages\django\core\handlers\exception.py", line 41, in inner
    response = get_response(request)
  File "D:\PV\My_work\splutsk\dev_build\venv\lib\site-packages\django\core\handlers\base.py", line 217, in _get_response
    response = self.process_exception_by_middleware(e, request)
  File "D:\PV\My_work\splutsk\dev_build\venv\lib\site-packages\django\core\handlers\base.py", line 215, in _get_response
    response = response.render()
  File "D:\PV\My_work\splutsk\dev_build\venv\lib\site-packages\django\template\response.py", line 107, in render
    self.content = self.rendered_content
  File "D:\PV\My_work\splutsk\dev_build\venv\lib\site-packages\rest_framework\response.py", line 72, in rendered_content
    ret = renderer.render(self.data, accepted_media_type, context)
  File "D:\PV\My_work\splutsk\dev_build\venv\lib\site-packages\rest_framework\renderers.py", line 105, in render
    allow_nan=not self.strict, separators=separators
  File "D:\PV\My_work\splutsk\dev_build\venv\lib\site-packages\rest_framework\utils\json.py", line 28, in dumps
    return json.dumps(*args, **kwargs)
  File "C:\Users\PV\AppData\Local\Programs\Python\Python36-32\lib\json\__init__.py", line 238, in dumps
    **kw).encode(obj)
  File "C:\Users\PV\AppData\Local\Programs\Python\Python36-32\lib\json\encoder.py", line 199, in encode
    chunks = self.iterencode(o, _one_shot=True)
  File "C:\Users\PV\AppData\Local\Programs\Python\Python36-32\lib\json\encoder.py", line 257, in iterencode
    return _iterencode(o, 0)
  File "D:\PV\My_work\splutsk\dev_build\venv\lib\site-packages\rest_framework\utils\encoders.py", line 68, in default
    return super(JSONEncoder, self).default(obj)
  File "C:\Users\PV\AppData\Local\Programs\Python\Python36-32\lib\json\encoder.py", line 180, in default
    o.__class__.__name__)
TypeError: Object of type 'Response' is not JSON serializable
01/17 23:06:45: ERROR >> "POST /api-token-auth/ HTTP/1.1" 500 111034
01/17 23:12:38: INFO >> Token for user with email <BoundField value=pvpasha@meta.ua errors=None> was save
01/17 23:12:39: ERROR >> Internal Server Error: /api-token-auth/
Traceback (most recent call last):
  File "D:\PV\My_work\splutsk\dev_build\venv\lib\site-packages\django\core\handlers\exception.py", line 41, in inner
    response = get_response(request)
  File "D:\PV\My_work\splutsk\dev_build\venv\lib\site-packages\django\core\handlers\base.py", line 187, in _get_response
    response = self.process_exception_by_middleware(e, request)
  File "D:\PV\My_work\splutsk\dev_build\venv\lib\site-packages\django\core\handlers\base.py", line 185, in _get_response
    response = wrapped_callback(request, *callback_args, **callback_kwargs)
  File "D:\PV\My_work\splutsk\dev_build\venv\lib\site-packages\django\views\decorators\csrf.py", line 58, in wrapped_view
    return view_func(*args, **kwargs)
  File "D:\PV\My_work\splutsk\dev_build\venv\lib\site-packages\django\views\generic\base.py", line 68, in view
    return self.dispatch(request, *args, **kwargs)
  File "D:\PV\My_work\splutsk\dev_build\venv\lib\site-packages\rest_framework\views.py", line 489, in dispatch
    response = self.handle_exception(exc)
  File "D:\PV\My_work\splutsk\dev_build\venv\lib\site-packages\rest_framework\views.py", line 449, in handle_exception
    self.raise_uncaught_exception(exc)
  File "D:\PV\My_work\splutsk\dev_build\venv\lib\site-packages\rest_framework\views.py", line 486, in dispatch
    response = handler(request, *args, **kwargs)
  File "D:\PV\My_work\splutsk\dev_build\venv\lib\site-packages\rest_framework_jwt\views.py", line 60, in post
    response_data = jwt_response_payload_handler(token, user, request)
  File "D:\PV\My_work\splutsk\dev_build\api\accounts\views.py", line 141, in jwt_response_handler_user
    {'token': token_data['jwt_token']},
  File "D:\PV\My_work\splutsk\dev_build\venv\lib\site-packages\django\http\response.py", line 524, in __init__
    'In order to allow non-dict objects to be serialized set the '
TypeError: In order to allow non-dict objects to be serialized set the safe parameter to False.
01/17 23:12:39: ERROR >> "POST /api-token-auth/ HTTP/1.1" 500 22782
01/17 23:14:12: INFO >> Token for user with email <BoundField value=pvpasha@meta.ua errors=None> was save
01/17 23:14:14: ERROR >> Internal Server Error: /api-token-auth/
Traceback (most recent call last):
  File "D:\PV\My_work\splutsk\dev_build\venv\lib\site-packages\django\core\handlers\exception.py", line 41, in inner
    response = get_response(request)
  File "D:\PV\My_work\splutsk\dev_build\venv\lib\site-packages\django\core\handlers\base.py", line 187, in _get_response
    response = self.process_exception_by_middleware(e, request)
  File "D:\PV\My_work\splutsk\dev_build\venv\lib\site-packages\django\core\handlers\base.py", line 185, in _get_response
    response = wrapped_callback(request, *callback_args, **callback_kwargs)
  File "D:\PV\My_work\splutsk\dev_build\venv\lib\site-packages\django\views\decorators\csrf.py", line 58, in wrapped_view
    return view_func(*args, **kwargs)
  File "D:\PV\My_work\splutsk\dev_build\venv\lib\site-packages\django\views\generic\base.py", line 68, in view
    return self.dispatch(request, *args, **kwargs)
  File "D:\PV\My_work\splutsk\dev_build\venv\lib\site-packages\rest_framework\views.py", line 489, in dispatch
    response = self.handle_exception(exc)
  File "D:\PV\My_work\splutsk\dev_build\venv\lib\site-packages\rest_framework\views.py", line 449, in handle_exception
    self.raise_uncaught_exception(exc)
  File "D:\PV\My_work\splutsk\dev_build\venv\lib\site-packages\rest_framework\views.py", line 486, in dispatch
    response = handler(request, *args, **kwargs)
  File "D:\PV\My_work\splutsk\dev_build\venv\lib\site-packages\rest_framework_jwt\views.py", line 60, in post
    response_data = jwt_response_payload_handler(token, user, request)
  File "D:\PV\My_work\splutsk\dev_build\api\accounts\views.py", line 143, in jwt_response_handler_user
    headers={'Access-Control-Allow-Origin': '*'}
  File "D:\PV\My_work\splutsk\dev_build\venv\lib\site-packages\django\http\response.py", line 524, in __init__
    'In order to allow non-dict objects to be serialized set the '
TypeError: In order to allow non-dict objects to be serialized set the safe parameter to False.
01/17 23:14:14: ERROR >> "POST /api-token-auth/ HTTP/1.1" 500 22791
01/17 23:15:33: INFO >> Token for user with email <BoundField value=pvpasha@meta.ua errors=None> was save
01/17 23:15:34: ERROR >> Internal Server Error: /api-token-auth/
Traceback (most recent call last):
  File "D:\PV\My_work\splutsk\dev_build\venv\lib\site-packages\django\core\handlers\exception.py", line 41, in inner
    response = get_response(request)
  File "D:\PV\My_work\splutsk\dev_build\venv\lib\site-packages\django\core\handlers\base.py", line 187, in _get_response
    response = self.process_exception_by_middleware(e, request)
  File "D:\PV\My_work\splutsk\dev_build\venv\lib\site-packages\django\core\handlers\base.py", line 185, in _get_response
    response = wrapped_callback(request, *callback_args, **callback_kwargs)
  File "D:\PV\My_work\splutsk\dev_build\venv\lib\site-packages\django\views\decorators\csrf.py", line 58, in wrapped_view
    return view_func(*args, **kwargs)
  File "D:\PV\My_work\splutsk\dev_build\venv\lib\site-packages\django\views\generic\base.py", line 68, in view
    return self.dispatch(request, *args, **kwargs)
  File "D:\PV\My_work\splutsk\dev_build\venv\lib\site-packages\rest_framework\views.py", line 489, in dispatch
    response = self.handle_exception(exc)
  File "D:\PV\My_work\splutsk\dev_build\venv\lib\site-packages\rest_framework\views.py", line 449, in handle_exception
    self.raise_uncaught_exception(exc)
  File "D:\PV\My_work\splutsk\dev_build\venv\lib\site-packages\rest_framework\views.py", line 486, in dispatch
    response = handler(request, *args, **kwargs)
  File "D:\PV\My_work\splutsk\dev_build\venv\lib\site-packages\rest_framework_jwt\views.py", line 60, in post
    response_data = jwt_response_payload_handler(token, user, request)
  File "D:\PV\My_work\splutsk\dev_build\api\accounts\views.py", line 144, in jwt_response_handler_user
    content_type='application/json'
  File "D:\PV\My_work\splutsk\dev_build\venv\lib\site-packages\django\http\response.py", line 524, in __init__
    'In order to allow non-dict objects to be serialized set the '
TypeError: In order to allow non-dict objects to be serialized set the safe parameter to False.
01/17 23:15:34: ERROR >> "POST /api-token-auth/ HTTP/1.1" 500 22778
01/17 23:34:11: INFO >> Token for user with email <BoundField value=pvpasha@meta.ua errors=None> was save
01/17 23:34:13: ERROR >> Internal Server Error: /api-token-auth/
Traceback (most recent call last):
  File "D:\PV\My_work\splutsk\dev_build\venv\lib\site-packages\django\core\handlers\exception.py", line 41, in inner
    response = get_response(request)
  File "D:\PV\My_work\splutsk\dev_build\venv\lib\site-packages\django\core\handlers\base.py", line 217, in _get_response
    response = self.process_exception_by_middleware(e, request)
  File "D:\PV\My_work\splutsk\dev_build\venv\lib\site-packages\django\core\handlers\base.py", line 215, in _get_response
    response = response.render()
  File "D:\PV\My_work\splutsk\dev_build\venv\lib\site-packages\django\template\response.py", line 107, in render
    self.content = self.rendered_content
  File "D:\PV\My_work\splutsk\dev_build\venv\lib\site-packages\rest_framework\response.py", line 72, in rendered_content
    ret = renderer.render(self.data, accepted_media_type, context)
  File "D:\PV\My_work\splutsk\dev_build\venv\lib\site-packages\rest_framework\renderers.py", line 105, in render
    allow_nan=not self.strict, separators=separators
  File "D:\PV\My_work\splutsk\dev_build\venv\lib\site-packages\rest_framework\utils\json.py", line 28, in dumps
    return json.dumps(*args, **kwargs)
  File "C:\Users\PV\AppData\Local\Programs\Python\Python36-32\lib\json\__init__.py", line 238, in dumps
    **kw).encode(obj)
  File "C:\Users\PV\AppData\Local\Programs\Python\Python36-32\lib\json\encoder.py", line 199, in encode
    chunks = self.iterencode(o, _one_shot=True)
  File "C:\Users\PV\AppData\Local\Programs\Python\Python36-32\lib\json\encoder.py", line 257, in iterencode
    return _iterencode(o, 0)
  File "D:\PV\My_work\splutsk\dev_build\venv\lib\site-packages\rest_framework\utils\encoders.py", line 68, in default
    return super(JSONEncoder, self).default(obj)
  File "C:\Users\PV\AppData\Local\Programs\Python\Python36-32\lib\json\encoder.py", line 180, in default
    o.__class__.__name__)
TypeError: Object of type 'Response' is not JSON serializable
01/17 23:34:13: ERROR >> "POST /api-token-auth/ HTTP/1.1" 500 111034
01/18 00:28:46: INFO >> Token for user with email <BoundField value=pvpasha@meta.ua errors=None> was save
01/18 00:28:48: ERROR >> Internal Server Error: /api-token-auth/
Traceback (most recent call last):
  File "D:\PV\My_work\splutsk\dev_build\venv\lib\site-packages\django\core\handlers\exception.py", line 41, in inner
    response = get_response(request)
  File "D:\PV\My_work\splutsk\dev_build\venv\lib\site-packages\django\core\handlers\base.py", line 217, in _get_response
    response = self.process_exception_by_middleware(e, request)
  File "D:\PV\My_work\splutsk\dev_build\venv\lib\site-packages\django\core\handlers\base.py", line 215, in _get_response
    response = response.render()
  File "D:\PV\My_work\splutsk\dev_build\venv\lib\site-packages\django\template\response.py", line 107, in render
    self.content = self.rendered_content
  File "D:\PV\My_work\splutsk\dev_build\venv\lib\site-packages\rest_framework\response.py", line 72, in rendered_content
    ret = renderer.render(self.data, accepted_media_type, context)
  File "D:\PV\My_work\splutsk\dev_build\venv\lib\site-packages\rest_framework\renderers.py", line 105, in render
    allow_nan=not self.strict, separators=separators
  File "D:\PV\My_work\splutsk\dev_build\venv\lib\site-packages\rest_framework\utils\json.py", line 28, in dumps
    return json.dumps(*args, **kwargs)
  File "C:\Users\PV\AppData\Local\Programs\Python\Python36-32\lib\json\__init__.py", line 238, in dumps
    **kw).encode(obj)
  File "C:\Users\PV\AppData\Local\Programs\Python\Python36-32\lib\json\encoder.py", line 199, in encode
    chunks = self.iterencode(o, _one_shot=True)
  File "C:\Users\PV\AppData\Local\Programs\Python\Python36-32\lib\json\encoder.py", line 257, in iterencode
    return _iterencode(o, 0)
  File "D:\PV\My_work\splutsk\dev_build\venv\lib\site-packages\rest_framework\utils\encoders.py", line 68, in default
    return super(JSONEncoder, self).default(obj)
  File "C:\Users\PV\AppData\Local\Programs\Python\Python36-32\lib\json\encoder.py", line 180, in default
    o.__class__.__name__)
TypeError: Object of type 'Response' is not JSON serializable
01/18 00:28:48: ERROR >> "POST /api-token-auth/ HTTP/1.1" 500 111034
01/18 00:28:53: WARNING >> "POST /api-token-auth/ HTTP/1.1" 415 62
01/18 00:28:57: INFO >> Token for user with email <BoundField value=pvpasha@meta.ua errors=None> was save
01/18 00:28:57: ERROR >> Internal Server Error: /api-token-auth/
Traceback (most recent call last):
  File "D:\PV\My_work\splutsk\dev_build\venv\lib\site-packages\django\core\handlers\exception.py", line 41, in inner
    response = get_response(request)
  File "D:\PV\My_work\splutsk\dev_build\venv\lib\site-packages\django\core\handlers\base.py", line 217, in _get_response
    response = self.process_exception_by_middleware(e, request)
  File "D:\PV\My_work\splutsk\dev_build\venv\lib\site-packages\django\core\handlers\base.py", line 215, in _get_response
    response = response.render()
  File "D:\PV\My_work\splutsk\dev_build\venv\lib\site-packages\django\template\response.py", line 107, in render
    self.content = self.rendered_content
  File "D:\PV\My_work\splutsk\dev_build\venv\lib\site-packages\rest_framework\response.py", line 72, in rendered_content
    ret = renderer.render(self.data, accepted_media_type, context)
  File "D:\PV\My_work\splutsk\dev_build\venv\lib\site-packages\rest_framework\renderers.py", line 105, in render
    allow_nan=not self.strict, separators=separators
  File "D:\PV\My_work\splutsk\dev_build\venv\lib\site-packages\rest_framework\utils\json.py", line 28, in dumps
    return json.dumps(*args, **kwargs)
  File "C:\Users\PV\AppData\Local\Programs\Python\Python36-32\lib\json\__init__.py", line 238, in dumps
    **kw).encode(obj)
  File "C:\Users\PV\AppData\Local\Programs\Python\Python36-32\lib\json\encoder.py", line 199, in encode
    chunks = self.iterencode(o, _one_shot=True)
  File "C:\Users\PV\AppData\Local\Programs\Python\Python36-32\lib\json\encoder.py", line 257, in iterencode
    return _iterencode(o, 0)
  File "D:\PV\My_work\splutsk\dev_build\venv\lib\site-packages\rest_framework\utils\encoders.py", line 68, in default
    return super(JSONEncoder, self).default(obj)
  File "C:\Users\PV\AppData\Local\Programs\Python\Python36-32\lib\json\encoder.py", line 180, in default
    o.__class__.__name__)
TypeError: Object of type 'Response' is not JSON serializable
01/18 00:28:58: ERROR >> "POST /api-token-auth/ HTTP/1.1" 500 111034
01/18 00:33:37: INFO >> Token for user with email <BoundField value=pvpasha@meta.ua errors=None> was save
01/18 00:33:38: ERROR >> Internal Server Error: /api-token-auth/
Traceback (most recent call last):
  File "D:\PV\My_work\splutsk\dev_build\venv\lib\site-packages\django\core\handlers\exception.py", line 41, in inner
    response = get_response(request)
  File "D:\PV\My_work\splutsk\dev_build\venv\lib\site-packages\django\core\handlers\base.py", line 187, in _get_response
    response = self.process_exception_by_middleware(e, request)
  File "D:\PV\My_work\splutsk\dev_build\venv\lib\site-packages\django\core\handlers\base.py", line 185, in _get_response
    response = wrapped_callback(request, *callback_args, **callback_kwargs)
  File "D:\PV\My_work\splutsk\dev_build\venv\lib\site-packages\django\views\decorators\csrf.py", line 58, in wrapped_view
    return view_func(*args, **kwargs)
  File "D:\PV\My_work\splutsk\dev_build\venv\lib\site-packages\django\views\generic\base.py", line 68, in view
    return self.dispatch(request, *args, **kwargs)
  File "D:\PV\My_work\splutsk\dev_build\venv\lib\site-packages\rest_framework\views.py", line 489, in dispatch
    response = self.handle_exception(exc)
  File "D:\PV\My_work\splutsk\dev_build\venv\lib\site-packages\rest_framework\views.py", line 449, in handle_exception
    self.raise_uncaught_exception(exc)
  File "D:\PV\My_work\splutsk\dev_build\venv\lib\site-packages\rest_framework\views.py", line 486, in dispatch
    response = handler(request, *args, **kwargs)
  File "D:\PV\My_work\splutsk\dev_build\venv\lib\site-packages\rest_framework_jwt\views.py", line 60, in post
    response_data = jwt_response_payload_handler(token, user, request)
  File "D:\PV\My_work\splutsk\dev_build\api\accounts\views.py", line 145, in jwt_response_handler_user
    return JsonResponse(response_data)
  File "D:\PV\My_work\splutsk\dev_build\venv\lib\site-packages\django\http\response.py", line 524, in __init__
    'In order to allow non-dict objects to be serialized set the '
TypeError: In order to allow non-dict objects to be serialized set the safe parameter to False.
01/18 00:33:38: ERROR >> "POST /api-token-auth/ HTTP/1.1" 500 22777
01/18 00:36:07: INFO >> Token for user with email <BoundField value=pvpasha@meta.ua errors=None> was save
01/18 00:36:09: ERROR >> Internal Server Error: /api-token-auth/
Traceback (most recent call last):
  File "D:\PV\My_work\splutsk\dev_build\venv\lib\site-packages\django\core\handlers\exception.py", line 41, in inner
    response = get_response(request)
  File "D:\PV\My_work\splutsk\dev_build\venv\lib\site-packages\django\core\handlers\base.py", line 187, in _get_response
    response = self.process_exception_by_middleware(e, request)
  File "D:\PV\My_work\splutsk\dev_build\venv\lib\site-packages\django\core\handlers\base.py", line 185, in _get_response
    response = wrapped_callback(request, *callback_args, **callback_kwargs)
  File "D:\PV\My_work\splutsk\dev_build\venv\lib\site-packages\django\views\decorators\csrf.py", line 58, in wrapped_view
    return view_func(*args, **kwargs)
  File "D:\PV\My_work\splutsk\dev_build\venv\lib\site-packages\django\views\generic\base.py", line 68, in view
    return self.dispatch(request, *args, **kwargs)
  File "D:\PV\My_work\splutsk\dev_build\venv\lib\site-packages\rest_framework\views.py", line 489, in dispatch
    response = self.handle_exception(exc)
  File "D:\PV\My_work\splutsk\dev_build\venv\lib\site-packages\rest_framework\views.py", line 449, in handle_exception
    self.raise_uncaught_exception(exc)
  File "D:\PV\My_work\splutsk\dev_build\venv\lib\site-packages\rest_framework\views.py", line 486, in dispatch
    response = handler(request, *args, **kwargs)
  File "D:\PV\My_work\splutsk\dev_build\venv\lib\site-packages\rest_framework_jwt\views.py", line 60, in post
    response_data = jwt_response_payload_handler(token, user, request)
  File "D:\PV\My_work\splutsk\dev_build\api\accounts\views.py", line 144, in jwt_response_handler_user
    content_type='application/json')
  File "D:\PV\My_work\splutsk\dev_build\venv\lib\site-packages\rest_framework\response.py", line 40, in __init__
    raise AssertionError(msg)
AssertionError: You passed a Serializer instance as data, but probably meant to pass serialized `.data` or `.error`. representation.
01/18 00:36:09: ERROR >> "POST /api-token-auth/ HTTP/1.1" 500 22814
01/18 00:36:33: INFO >> Token for user with email <BoundField value=pvpasha@meta.ua errors=None> was save
01/18 00:36:34: ERROR >> Internal Server Error: /api-token-auth/
Traceback (most recent call last):
  File "D:\PV\My_work\splutsk\dev_build\venv\lib\site-packages\django\core\handlers\exception.py", line 41, in inner
    response = get_response(request)
  File "D:\PV\My_work\splutsk\dev_build\venv\lib\site-packages\django\core\handlers\base.py", line 217, in _get_response
    response = self.process_exception_by_middleware(e, request)
  File "D:\PV\My_work\splutsk\dev_build\venv\lib\site-packages\django\core\handlers\base.py", line 215, in _get_response
    response = response.render()
  File "D:\PV\My_work\splutsk\dev_build\venv\lib\site-packages\django\template\response.py", line 107, in render
    self.content = self.rendered_content
  File "D:\PV\My_work\splutsk\dev_build\venv\lib\site-packages\rest_framework\response.py", line 72, in rendered_content
    ret = renderer.render(self.data, accepted_media_type, context)
  File "D:\PV\My_work\splutsk\dev_build\venv\lib\site-packages\rest_framework\renderers.py", line 105, in render
    allow_nan=not self.strict, separators=separators
  File "D:\PV\My_work\splutsk\dev_build\venv\lib\site-packages\rest_framework\utils\json.py", line 28, in dumps
    return json.dumps(*args, **kwargs)
  File "C:\Users\PV\AppData\Local\Programs\Python\Python36-32\lib\json\__init__.py", line 238, in dumps
    **kw).encode(obj)
  File "C:\Users\PV\AppData\Local\Programs\Python\Python36-32\lib\json\encoder.py", line 199, in encode
    chunks = self.iterencode(o, _one_shot=True)
  File "C:\Users\PV\AppData\Local\Programs\Python\Python36-32\lib\json\encoder.py", line 257, in iterencode
    return _iterencode(o, 0)
  File "D:\PV\My_work\splutsk\dev_build\venv\lib\site-packages\rest_framework\utils\encoders.py", line 68, in default
    return super(JSONEncoder, self).default(obj)
  File "C:\Users\PV\AppData\Local\Programs\Python\Python36-32\lib\json\encoder.py", line 180, in default
    o.__class__.__name__)
TypeError: Object of type 'Response' is not JSON serializable
01/18 00:36:35: ERROR >> "POST /api-token-auth/ HTTP/1.1" 500 111034
01/18 00:46:50: INFO >> Token for user with email <BoundField value=pvpasha@meta.ua errors=None> was save
01/18 00:46:51: ERROR >> Internal Server Error: /api-token-auth/
Traceback (most recent call last):
  File "D:\PV\My_work\splutsk\dev_build\venv\lib\site-packages\django\core\handlers\exception.py", line 41, in inner
    response = get_response(request)
  File "D:\PV\My_work\splutsk\dev_build\venv\lib\site-packages\django\core\handlers\base.py", line 187, in _get_response
    response = self.process_exception_by_middleware(e, request)
  File "D:\PV\My_work\splutsk\dev_build\venv\lib\site-packages\django\core\handlers\base.py", line 185, in _get_response
    response = wrapped_callback(request, *callback_args, **callback_kwargs)
  File "D:\PV\My_work\splutsk\dev_build\venv\lib\site-packages\django\views\decorators\csrf.py", line 58, in wrapped_view
    return view_func(*args, **kwargs)
  File "D:\PV\My_work\splutsk\dev_build\venv\lib\site-packages\django\views\generic\base.py", line 68, in view
    return self.dispatch(request, *args, **kwargs)
  File "D:\PV\My_work\splutsk\dev_build\venv\lib\site-packages\rest_framework\views.py", line 489, in dispatch
    response = self.handle_exception(exc)
  File "D:\PV\My_work\splutsk\dev_build\venv\lib\site-packages\rest_framework\views.py", line 449, in handle_exception
    self.raise_uncaught_exception(exc)
  File "D:\PV\My_work\splutsk\dev_build\venv\lib\site-packages\rest_framework\views.py", line 486, in dispatch
    response = handler(request, *args, **kwargs)
  File "D:\PV\My_work\splutsk\dev_build\venv\lib\site-packages\rest_framework_jwt\views.py", line 60, in post
    response_data = jwt_response_payload_handler(token, user, request)
  File "D:\PV\My_work\splutsk\dev_build\api\accounts\views.py", line 141, in jwt_response_handler_user
    response['data'] = token_data['jwt_token'].__dict__
AttributeError: 'str' object has no attribute '__dict__'
01/18 00:46:51: ERROR >> "POST /api-token-auth/ HTTP/1.1" 500 22531
01/18 00:47:50: INFO >> Token for user with email <BoundField value=pvpasha@meta.ua errors=None> was save
01/18 00:47:52: ERROR >> Internal Server Error: /api-token-auth/
Traceback (most recent call last):
  File "D:\PV\My_work\splutsk\dev_build\venv\lib\site-packages\django\core\handlers\exception.py", line 41, in inner
    response = get_response(request)
  File "D:\PV\My_work\splutsk\dev_build\venv\lib\site-packages\django\core\handlers\base.py", line 187, in _get_response
    response = self.process_exception_by_middleware(e, request)
  File "D:\PV\My_work\splutsk\dev_build\venv\lib\site-packages\django\core\handlers\base.py", line 185, in _get_response
    response = wrapped_callback(request, *callback_args, **callback_kwargs)
  File "D:\PV\My_work\splutsk\dev_build\venv\lib\site-packages\django\views\decorators\csrf.py", line 58, in wrapped_view
    return view_func(*args, **kwargs)
  File "D:\PV\My_work\splutsk\dev_build\venv\lib\site-packages\django\views\generic\base.py", line 68, in view
    return self.dispatch(request, *args, **kwargs)
  File "D:\PV\My_work\splutsk\dev_build\venv\lib\site-packages\rest_framework\views.py", line 489, in dispatch
    response = self.handle_exception(exc)
  File "D:\PV\My_work\splutsk\dev_build\venv\lib\site-packages\rest_framework\views.py", line 449, in handle_exception
    self.raise_uncaught_exception(exc)
  File "D:\PV\My_work\splutsk\dev_build\venv\lib\site-packages\rest_framework\views.py", line 486, in dispatch
    response = handler(request, *args, **kwargs)
  File "D:\PV\My_work\splutsk\dev_build\venv\lib\site-packages\rest_framework_jwt\views.py", line 60, in post
    response_data = jwt_response_payload_handler(token, user, request)
  File "D:\PV\My_work\splutsk\dev_build\api\accounts\views.py", line 141, in jwt_response_handler_user
    response['data'] = token_data['jwt_token']
NameError: name 'response' is not defined
01/18 00:47:52: ERROR >> "POST /api-token-auth/ HTTP/1.1" 500 22492
01/18 00:49:11: INFO >> Token for user with email <BoundField value=pvpasha@meta.ua errors=None> was save
01/18 00:49:13: ERROR >> Internal Server Error: /api-token-auth/
Traceback (most recent call last):
  File "D:\PV\My_work\splutsk\dev_build\venv\lib\site-packages\django\core\handlers\exception.py", line 41, in inner
    response = get_response(request)
  File "D:\PV\My_work\splutsk\dev_build\venv\lib\site-packages\django\core\handlers\base.py", line 187, in _get_response
    response = self.process_exception_by_middleware(e, request)
  File "D:\PV\My_work\splutsk\dev_build\venv\lib\site-packages\django\core\handlers\base.py", line 185, in _get_response
    response = wrapped_callback(request, *callback_args, **callback_kwargs)
  File "D:\PV\My_work\splutsk\dev_build\venv\lib\site-packages\django\views\decorators\csrf.py", line 58, in wrapped_view
    return view_func(*args, **kwargs)
  File "D:\PV\My_work\splutsk\dev_build\venv\lib\site-packages\django\views\generic\base.py", line 68, in view
    return self.dispatch(request, *args, **kwargs)
  File "D:\PV\My_work\splutsk\dev_build\venv\lib\site-packages\rest_framework\views.py", line 489, in dispatch
    response = self.handle_exception(exc)
  File "D:\PV\My_work\splutsk\dev_build\venv\lib\site-packages\rest_framework\views.py", line 449, in handle_exception
    self.raise_uncaught_exception(exc)
  File "D:\PV\My_work\splutsk\dev_build\venv\lib\site-packages\rest_framework\views.py", line 486, in dispatch
    response = handler(request, *args, **kwargs)
  File "D:\PV\My_work\splutsk\dev_build\venv\lib\site-packages\rest_framework_jwt\views.py", line 60, in post
    response_data = jwt_response_payload_handler(token, user, request)
  File "D:\PV\My_work\splutsk\dev_build\api\accounts\views.py", line 146, in jwt_response_handler_user
    return Response(response.__dict__)
AttributeError: 'dict' object has no attribute '__dict__'
01/18 00:49:13: ERROR >> "POST /api-token-auth/ HTTP/1.1" 500 22516
01/18 00:49:39: INFO >> Token for user with email <BoundField value=pvpasha@meta.ua errors=None> was save
01/18 00:49:40: ERROR >> Internal Server Error: /api-token-auth/
Traceback (most recent call last):
  File "D:\PV\My_work\splutsk\dev_build\venv\lib\site-packages\django\core\handlers\exception.py", line 41, in inner
    response = get_response(request)
  File "D:\PV\My_work\splutsk\dev_build\venv\lib\site-packages\django\core\handlers\base.py", line 217, in _get_response
    response = self.process_exception_by_middleware(e, request)
  File "D:\PV\My_work\splutsk\dev_build\venv\lib\site-packages\django\core\handlers\base.py", line 215, in _get_response
    response = response.render()
  File "D:\PV\My_work\splutsk\dev_build\venv\lib\site-packages\django\template\response.py", line 107, in render
    self.content = self.rendered_content
  File "D:\PV\My_work\splutsk\dev_build\venv\lib\site-packages\rest_framework\response.py", line 72, in rendered_content
    ret = renderer.render(self.data, accepted_media_type, context)
  File "D:\PV\My_work\splutsk\dev_build\venv\lib\site-packages\rest_framework\renderers.py", line 105, in render
    allow_nan=not self.strict, separators=separators
  File "D:\PV\My_work\splutsk\dev_build\venv\lib\site-packages\rest_framework\utils\json.py", line 28, in dumps
    return json.dumps(*args, **kwargs)
  File "C:\Users\PV\AppData\Local\Programs\Python\Python36-32\lib\json\__init__.py", line 238, in dumps
    **kw).encode(obj)
  File "C:\Users\PV\AppData\Local\Programs\Python\Python36-32\lib\json\encoder.py", line 199, in encode
    chunks = self.iterencode(o, _one_shot=True)
  File "C:\Users\PV\AppData\Local\Programs\Python\Python36-32\lib\json\encoder.py", line 257, in iterencode
    return _iterencode(o, 0)
  File "D:\PV\My_work\splutsk\dev_build\venv\lib\site-packages\rest_framework\utils\encoders.py", line 68, in default
    return super(JSONEncoder, self).default(obj)
  File "C:\Users\PV\AppData\Local\Programs\Python\Python36-32\lib\json\encoder.py", line 180, in default
    o.__class__.__name__)
TypeError: Object of type 'Response' is not JSON serializable
01/18 00:49:41: ERROR >> "POST /api-token-auth/ HTTP/1.1" 500 111034
01/18 00:51:30: INFO >> Token for user with email <BoundField value=pvpasha@meta.ua errors=None> was save
01/18 00:51:31: ERROR >> Internal Server Error: /api-token-auth/
Traceback (most recent call last):
  File "D:\PV\My_work\splutsk\dev_build\venv\lib\site-packages\django\core\handlers\exception.py", line 41, in inner
    response = get_response(request)
  File "D:\PV\My_work\splutsk\dev_build\venv\lib\site-packages\django\core\handlers\base.py", line 217, in _get_response
    response = self.process_exception_by_middleware(e, request)
  File "D:\PV\My_work\splutsk\dev_build\venv\lib\site-packages\django\core\handlers\base.py", line 215, in _get_response
    response = response.render()
  File "D:\PV\My_work\splutsk\dev_build\venv\lib\site-packages\django\template\response.py", line 107, in render
    self.content = self.rendered_content
  File "D:\PV\My_work\splutsk\dev_build\venv\lib\site-packages\rest_framework\response.py", line 72, in rendered_content
    ret = renderer.render(self.data, accepted_media_type, context)
  File "D:\PV\My_work\splutsk\dev_build\venv\lib\site-packages\rest_framework\renderers.py", line 105, in render
    allow_nan=not self.strict, separators=separators
  File "D:\PV\My_work\splutsk\dev_build\venv\lib\site-packages\rest_framework\utils\json.py", line 28, in dumps
    return json.dumps(*args, **kwargs)
  File "C:\Users\PV\AppData\Local\Programs\Python\Python36-32\lib\json\__init__.py", line 238, in dumps
    **kw).encode(obj)
  File "C:\Users\PV\AppData\Local\Programs\Python\Python36-32\lib\json\encoder.py", line 199, in encode
    chunks = self.iterencode(o, _one_shot=True)
  File "C:\Users\PV\AppData\Local\Programs\Python\Python36-32\lib\json\encoder.py", line 257, in iterencode
    return _iterencode(o, 0)
  File "D:\PV\My_work\splutsk\dev_build\venv\lib\site-packages\rest_framework\utils\encoders.py", line 68, in default
    return super(JSONEncoder, self).default(obj)
  File "C:\Users\PV\AppData\Local\Programs\Python\Python36-32\lib\json\encoder.py", line 180, in default
    o.__class__.__name__)
TypeError: Object of type 'Response' is not JSON serializable
01/18 00:51:31: ERROR >> "POST /api-token-auth/ HTTP/1.1" 500 111034
01/18 01:05:27: INFO >> Token for user with email <BoundField value=pvpasha@meta.ua errors=None> was save
01/18 01:05:28: ERROR >> Internal Server Error: /api-token-auth/
Traceback (most recent call last):
  File "D:\PV\My_work\splutsk\dev_build\venv\lib\site-packages\django\core\handlers\exception.py", line 41, in inner
    response = get_response(request)
  File "D:\PV\My_work\splutsk\dev_build\venv\lib\site-packages\django\core\handlers\base.py", line 217, in _get_response
    response = self.process_exception_by_middleware(e, request)
  File "D:\PV\My_work\splutsk\dev_build\venv\lib\site-packages\django\core\handlers\base.py", line 215, in _get_response
    response = response.render()
  File "D:\PV\My_work\splutsk\dev_build\venv\lib\site-packages\django\template\response.py", line 107, in render
    self.content = self.rendered_content
  File "D:\PV\My_work\splutsk\dev_build\venv\lib\site-packages\rest_framework\response.py", line 72, in rendered_content
    ret = renderer.render(self.data, accepted_media_type, context)
  File "D:\PV\My_work\splutsk\dev_build\venv\lib\site-packages\rest_framework\renderers.py", line 105, in render
    allow_nan=not self.strict, separators=separators
  File "D:\PV\My_work\splutsk\dev_build\venv\lib\site-packages\rest_framework\utils\json.py", line 28, in dumps
    return json.dumps(*args, **kwargs)
  File "C:\Users\PV\AppData\Local\Programs\Python\Python36-32\lib\json\__init__.py", line 238, in dumps
    **kw).encode(obj)
  File "C:\Users\PV\AppData\Local\Programs\Python\Python36-32\lib\json\encoder.py", line 199, in encode
    chunks = self.iterencode(o, _one_shot=True)
  File "C:\Users\PV\AppData\Local\Programs\Python\Python36-32\lib\json\encoder.py", line 257, in iterencode
    return _iterencode(o, 0)
  File "D:\PV\My_work\splutsk\dev_build\venv\lib\site-packages\rest_framework\utils\encoders.py", line 68, in default
    return super(JSONEncoder, self).default(obj)
  File "C:\Users\PV\AppData\Local\Programs\Python\Python36-32\lib\json\encoder.py", line 180, in default
    o.__class__.__name__)
TypeError: Object of type 'Response' is not JSON serializable
01/18 01:05:28: ERROR >> "POST /api-token-auth/ HTTP/1.1" 500 111034
01/18 01:06:33: INFO >> Token for user with email <BoundField value=pvpasha@meta.ua errors=None> was save
01/18 01:06:35: ERROR >> Internal Server Error: /api-token-auth/
Traceback (most recent call last):
  File "D:\PV\My_work\splutsk\dev_build\venv\lib\site-packages\django\core\handlers\exception.py", line 41, in inner
    response = get_response(request)
  File "D:\PV\My_work\splutsk\dev_build\venv\lib\site-packages\django\core\handlers\base.py", line 217, in _get_response
    response = self.process_exception_by_middleware(e, request)
  File "D:\PV\My_work\splutsk\dev_build\venv\lib\site-packages\django\core\handlers\base.py", line 215, in _get_response
    response = response.render()
  File "D:\PV\My_work\splutsk\dev_build\venv\lib\site-packages\django\template\response.py", line 107, in render
    self.content = self.rendered_content
  File "D:\PV\My_work\splutsk\dev_build\venv\lib\site-packages\rest_framework\response.py", line 72, in rendered_content
    ret = renderer.render(self.data, accepted_media_type, context)
  File "D:\PV\My_work\splutsk\dev_build\venv\lib\site-packages\rest_framework\renderers.py", line 105, in render
    allow_nan=not self.strict, separators=separators
  File "D:\PV\My_work\splutsk\dev_build\venv\lib\site-packages\rest_framework\utils\json.py", line 28, in dumps
    return json.dumps(*args, **kwargs)
  File "C:\Users\PV\AppData\Local\Programs\Python\Python36-32\lib\json\__init__.py", line 238, in dumps
    **kw).encode(obj)
  File "C:\Users\PV\AppData\Local\Programs\Python\Python36-32\lib\json\encoder.py", line 199, in encode
    chunks = self.iterencode(o, _one_shot=True)
  File "C:\Users\PV\AppData\Local\Programs\Python\Python36-32\lib\json\encoder.py", line 257, in iterencode
    return _iterencode(o, 0)
  File "D:\PV\My_work\splutsk\dev_build\venv\lib\site-packages\rest_framework\utils\encoders.py", line 68, in default
    return super(JSONEncoder, self).default(obj)
  File "C:\Users\PV\AppData\Local\Programs\Python\Python36-32\lib\json\encoder.py", line 180, in default
    o.__class__.__name__)
TypeError: Object of type 'Response' is not JSON serializable
01/18 01:06:35: ERROR >> "POST /api-token-auth/ HTTP/1.1" 500 111034
01/18 01:07:04: INFO >> Token for user with email <BoundField value=pvpasha@meta.ua errors=None> was save
01/18 01:07:06: ERROR >> Internal Server Error: /api-token-auth/
Traceback (most recent call last):
  File "D:\PV\My_work\splutsk\dev_build\venv\lib\site-packages\django\core\handlers\exception.py", line 41, in inner
    response = get_response(request)
  File "D:\PV\My_work\splutsk\dev_build\venv\lib\site-packages\django\core\handlers\base.py", line 217, in _get_response
    response = self.process_exception_by_middleware(e, request)
  File "D:\PV\My_work\splutsk\dev_build\venv\lib\site-packages\django\core\handlers\base.py", line 215, in _get_response
    response = response.render()
  File "D:\PV\My_work\splutsk\dev_build\venv\lib\site-packages\django\template\response.py", line 107, in render
    self.content = self.rendered_content
  File "D:\PV\My_work\splutsk\dev_build\venv\lib\site-packages\rest_framework\response.py", line 72, in rendered_content
    ret = renderer.render(self.data, accepted_media_type, context)
  File "D:\PV\My_work\splutsk\dev_build\venv\lib\site-packages\rest_framework\renderers.py", line 105, in render
    allow_nan=not self.strict, separators=separators
  File "D:\PV\My_work\splutsk\dev_build\venv\lib\site-packages\rest_framework\utils\json.py", line 28, in dumps
    return json.dumps(*args, **kwargs)
  File "C:\Users\PV\AppData\Local\Programs\Python\Python36-32\lib\json\__init__.py", line 238, in dumps
    **kw).encode(obj)
  File "C:\Users\PV\AppData\Local\Programs\Python\Python36-32\lib\json\encoder.py", line 199, in encode
    chunks = self.iterencode(o, _one_shot=True)
  File "C:\Users\PV\AppData\Local\Programs\Python\Python36-32\lib\json\encoder.py", line 257, in iterencode
    return _iterencode(o, 0)
  File "D:\PV\My_work\splutsk\dev_build\venv\lib\site-packages\rest_framework\utils\encoders.py", line 68, in default
    return super(JSONEncoder, self).default(obj)
  File "C:\Users\PV\AppData\Local\Programs\Python\Python36-32\lib\json\encoder.py", line 180, in default
    o.__class__.__name__)
TypeError: Object of type 'Response' is not JSON serializable
01/18 01:07:06: ERROR >> "POST /api-token-auth/ HTTP/1.1" 500 111034
01/18 01:10:49: INFO >> Token for user with email <BoundField value=pvpasha@meta.ua errors=None> was save
01/18 01:10:50: ERROR >> Internal Server Error: /api-token-auth/
Traceback (most recent call last):
  File "D:\PV\My_work\splutsk\dev_build\venv\lib\site-packages\django\core\handlers\exception.py", line 41, in inner
    response = get_response(request)
  File "D:\PV\My_work\splutsk\dev_build\venv\lib\site-packages\django\core\handlers\base.py", line 217, in _get_response
    response = self.process_exception_by_middleware(e, request)
  File "D:\PV\My_work\splutsk\dev_build\venv\lib\site-packages\django\core\handlers\base.py", line 215, in _get_response
    response = response.render()
  File "D:\PV\My_work\splutsk\dev_build\venv\lib\site-packages\django\template\response.py", line 107, in render
    self.content = self.rendered_content
  File "D:\PV\My_work\splutsk\dev_build\venv\lib\site-packages\rest_framework\response.py", line 72, in rendered_content
    ret = renderer.render(self.data, accepted_media_type, context)
  File "D:\PV\My_work\splutsk\dev_build\venv\lib\site-packages\rest_framework\renderers.py", line 105, in render
    allow_nan=not self.strict, separators=separators
  File "D:\PV\My_work\splutsk\dev_build\venv\lib\site-packages\rest_framework\utils\json.py", line 28, in dumps
    return json.dumps(*args, **kwargs)
  File "C:\Users\PV\AppData\Local\Programs\Python\Python36-32\lib\json\__init__.py", line 238, in dumps
    **kw).encode(obj)
  File "C:\Users\PV\AppData\Local\Programs\Python\Python36-32\lib\json\encoder.py", line 199, in encode
    chunks = self.iterencode(o, _one_shot=True)
  File "C:\Users\PV\AppData\Local\Programs\Python\Python36-32\lib\json\encoder.py", line 257, in iterencode
    return _iterencode(o, 0)
  File "D:\PV\My_work\splutsk\dev_build\venv\lib\site-packages\rest_framework\utils\encoders.py", line 68, in default
    return super(JSONEncoder, self).default(obj)
  File "C:\Users\PV\AppData\Local\Programs\Python\Python36-32\lib\json\encoder.py", line 180, in default
    o.__class__.__name__)
TypeError: Object of type 'Response' is not JSON serializable
01/18 01:10:50: ERROR >> "POST /api-token-auth/ HTTP/1.1" 500 111034
01/18 01:17:03: INFO >> Token for user with email <BoundField value=pvpasha@meta.ua errors=None> was save
01/18 01:17:04: ERROR >> Internal Server Error: /api-token-auth/
Traceback (most recent call last):
  File "D:\PV\My_work\splutsk\dev_build\venv\lib\site-packages\django\core\handlers\exception.py", line 41, in inner
    response = get_response(request)
  File "D:\PV\My_work\splutsk\dev_build\venv\lib\site-packages\django\core\handlers\base.py", line 217, in _get_response
    response = self.process_exception_by_middleware(e, request)
  File "D:\PV\My_work\splutsk\dev_build\venv\lib\site-packages\django\core\handlers\base.py", line 215, in _get_response
    response = response.render()
  File "D:\PV\My_work\splutsk\dev_build\venv\lib\site-packages\django\template\response.py", line 107, in render
    self.content = self.rendered_content
  File "D:\PV\My_work\splutsk\dev_build\venv\lib\site-packages\rest_framework\response.py", line 72, in rendered_content
    ret = renderer.render(self.data, accepted_media_type, context)
  File "D:\PV\My_work\splutsk\dev_build\venv\lib\site-packages\rest_framework\renderers.py", line 105, in render
    allow_nan=not self.strict, separators=separators
  File "D:\PV\My_work\splutsk\dev_build\venv\lib\site-packages\rest_framework\utils\json.py", line 28, in dumps
    return json.dumps(*args, **kwargs)
  File "C:\Users\PV\AppData\Local\Programs\Python\Python36-32\lib\json\__init__.py", line 238, in dumps
    **kw).encode(obj)
  File "C:\Users\PV\AppData\Local\Programs\Python\Python36-32\lib\json\encoder.py", line 199, in encode
    chunks = self.iterencode(o, _one_shot=True)
  File "C:\Users\PV\AppData\Local\Programs\Python\Python36-32\lib\json\encoder.py", line 257, in iterencode
    return _iterencode(o, 0)
  File "D:\PV\My_work\splutsk\dev_build\venv\lib\site-packages\rest_framework\utils\encoders.py", line 68, in default
    return super(JSONEncoder, self).default(obj)
  File "C:\Users\PV\AppData\Local\Programs\Python\Python36-32\lib\json\encoder.py", line 180, in default
    o.__class__.__name__)
TypeError: Object of type 'Response' is not JSON serializable
01/18 01:17:04: ERROR >> "POST /api-token-auth/ HTTP/1.1" 500 111034
01/18 01:24:47: INFO >> Token for user with email <BoundField value=pvpasha@meta.ua errors=None> was save
01/18 01:24:48: INFO >> "POST /api-token-auth/ HTTP/1.1" 200 236
01/18 01:27:43: INFO >> "OPTIONS /api-token-auth/ HTTP/1.1" 200 498
01/18 01:27:44: INFO >> Token for user with email <BoundField value=pvpasha@meta.ua errors=None> was save
01/18 01:27:45: INFO >> "POST /api-token-auth/ HTTP/1.1" 200 236
01/18 10:42:04: INFO >> "OPTIONS /api-token-auth/ HTTP/1.1" 200 0
01/18 10:42:04: INFO >> Token for user with email <BoundField value=pvpasha@meta.ua errors=None> was save
01/18 10:42:06: INFO >> "POST /api-token-auth/ HTTP/1.1" 200 236
01/18 10:45:42: INFO >> Token for user with email <BoundField value=pvpasha@meta.ua errors=None> was save
01/18 10:45:42: INFO >> "POST /api-token-auth/ HTTP/1.1" 200 236
01/18 10:46:25: INFO >> Token for user with email <BoundField value=pvpasha@meta.ua errors=None> was save
01/18 10:46:26: INFO >> "POST /api-token-auth/ HTTP/1.1" 200 236
01/18 10:47:06: INFO >> Token for user with email <BoundField value=pvpasha@meta.ua errors=None> was save
01/18 10:47:07: INFO >> "POST /api-token-auth/ HTTP/1.1" 200 236
01/18 10:52:51: INFO >> "OPTIONS /api-token-auth/ HTTP/1.1" 200 0
01/18 10:52:52: INFO >> Token for user with email <BoundField value=pvpasha@meta.ua errors=None> was save
01/18 10:52:52: INFO >> "POST /api-token-auth/ HTTP/1.1" 200 236
01/18 10:54:28: WARNING >> "POST /api-token-auth/ HTTP/1.1" 400 57
01/18 10:54:31: WARNING >> "POST /api-token-auth/ HTTP/1.1" 400 57
01/18 10:54:31: WARNING >> "POST /api-token-auth/ HTTP/1.1" 400 57
01/18 10:54:32: WARNING >> "POST /api-token-auth/ HTTP/1.1" 400 57
01/18 10:54:32: WARNING >> "POST /api-token-auth/ HTTP/1.1" 400 57
01/18 11:13:20: INFO >> Token for user with email <BoundField value=pvpasha@meta.ua errors=None> was save
01/18 11:13:21: INFO >> "POST /api-token-auth/ HTTP/1.1" 200 236
01/18 11:13:33: WARNING >> "POST /api-token-auth/ HTTP/1.1" 400 57
01/18 11:13:59: WARNING >> "POST /api-token-auth/ HTTP/1.1" 400 57
01/22 11:11:18: INFO >> "OPTIONS /api-token-auth/ HTTP/1.1" 200 0
01/22 11:11:19: WARNING >> "POST /api-token-auth/ HTTP/1.1" 400 57
01/22 11:12:46: WARNING >> "POST /api-token-auth/ HTTP/1.1" 400 57
01/22 11:14:11: WARNING >> "POST /api-token-auth/ HTTP/1.1" 400 57
01/22 11:14:12: WARNING >> "POST /api-token-auth/ HTTP/1.1" 400 57
01/22 11:57:36: INFO >> "OPTIONS /api-token-auth/ HTTP/1.1" 200 0
01/22 11:57:37: WARNING >> "POST /api-token-auth/ HTTP/1.1" 400 57
01/22 11:58:20: WARNING >> "POST /api-token-auth/ HTTP/1.1" 400 57
01/22 11:58:39: WARNING >> "POST /api-token-auth/ HTTP/1.1" 400 57
01/22 11:59:56: WARNING >> "POST /api-token-auth/ HTTP/1.1" 400 57
01/22 12:00:07: INFO >> Token for user with email <BoundField value=pvpasha@meta.ua errors=None> was save
01/22 12:00:08: INFO >> "POST /api-token-auth/ HTTP/1.1" 200 261
01/22 17:17:53: INFO >> "OPTIONS /api-token-auth/ HTTP/1.1" 200 0
01/22 17:17:54: INFO >> Token for user with email <BoundField value=pvpasha@meta.ua errors=None> was save
01/22 17:17:55: ERROR >> Internal Server Error: /api-token-auth/
Traceback (most recent call last):
  File "D:\PV\My_work\splutsk\dev_build\venv\lib\site-packages\django\core\handlers\exception.py", line 41, in inner
    response = get_response(request)
  File "D:\PV\My_work\splutsk\dev_build\venv\lib\site-packages\django\core\handlers\base.py", line 217, in _get_response
    response = self.process_exception_by_middleware(e, request)
  File "D:\PV\My_work\splutsk\dev_build\venv\lib\site-packages\django\core\handlers\base.py", line 215, in _get_response
    response = response.render()
  File "D:\PV\My_work\splutsk\dev_build\venv\lib\site-packages\django\template\response.py", line 107, in render
    self.content = self.rendered_content
  File "D:\PV\My_work\splutsk\dev_build\venv\lib\site-packages\rest_framework\response.py", line 72, in rendered_content
    ret = renderer.render(self.data, accepted_media_type, context)
  File "D:\PV\My_work\splutsk\dev_build\venv\lib\site-packages\rest_framework\renderers.py", line 105, in render
    allow_nan=not self.strict, separators=separators
  File "D:\PV\My_work\splutsk\dev_build\venv\lib\site-packages\rest_framework\utils\json.py", line 28, in dumps
    return json.dumps(*args, **kwargs)
  File "C:\Users\PV\AppData\Local\Programs\Python\Python36-32\lib\json\__init__.py", line 238, in dumps
    **kw).encode(obj)
  File "C:\Users\PV\AppData\Local\Programs\Python\Python36-32\lib\json\encoder.py", line 199, in encode
    chunks = self.iterencode(o, _one_shot=True)
  File "C:\Users\PV\AppData\Local\Programs\Python\Python36-32\lib\json\encoder.py", line 257, in iterencode
    return _iterencode(o, 0)
  File "D:\PV\My_work\splutsk\dev_build\venv\lib\site-packages\rest_framework\utils\encoders.py", line 68, in default
    return super(JSONEncoder, self).default(obj)
  File "C:\Users\PV\AppData\Local\Programs\Python\Python36-32\lib\json\encoder.py", line 180, in default
    o.__class__.__name__)
TypeError: Object of type 'Response' is not JSON serializable
01/22 17:17:55: ERROR >> "POST /api-token-auth/ HTTP/1.1" 500 112006
01/22 17:19:08: INFO >> Token for user with email <BoundField value=pvpasha@meta.ua errors=None> was save
01/22 17:19:09: INFO >> "POST /api-token-auth/ HTTP/1.1" 200 262
01/22 17:23:02: INFO >> Token for user with email <BoundField value=pvpasha@meta.ua errors=None> was save
01/22 17:23:03: INFO >> "POST /api-token-auth/ HTTP/1.1" 200 262
01/22 17:32:41: INFO >> "OPTIONS /api-token-auth/ HTTP/1.1" 200 0
01/22 17:32:41: INFO >> Token for user with email <BoundField value=pvpasha@meta.ua errors=None> was save
01/22 17:32:42: INFO >> "POST /api-token-auth/ HTTP/1.1" 200 262
01/22 17:34:54: INFO >> Token for user with email <BoundField value=pvpasha@meta.ua errors=None> was save
01/22 17:34:55: INFO >> "POST /api-token-auth/ HTTP/1.1" 200 262
01/22 17:36:32: INFO >> Token for user with email <BoundField value=pvpasha@meta.ua errors=None> was save
01/22 17:36:33: INFO >> "POST /api-token-auth/ HTTP/1.1" 200 262
01/22 17:36:36: INFO >> Token for user with email <BoundField value=pvpasha@meta.ua errors=None> was save
01/22 17:36:37: INFO >> "POST /api-token-auth/ HTTP/1.1" 200 262
01/22 17:36:42: INFO >> Token for user with email <BoundField value=pvpasha@meta.ua errors=None> was save
01/22 17:36:43: INFO >> "POST /api-token-auth/ HTTP/1.1" 200 262
01/22 17:37:18: INFO >> Token for user with email <BoundField value=pvpasha@meta.ua errors=None> was save
01/22 17:37:19: INFO >> "POST /api-token-auth/ HTTP/1.1" 200 262
01/22 17:37:21: INFO >> Token for user with email <BoundField value=pvpasha@meta.ua errors=None> was save
01/22 17:37:21: INFO >> "POST /api-token-auth/ HTTP/1.1" 200 262
01/22 17:37:23: INFO >> Token for user with email <BoundField value=pvpasha@meta.ua errors=None> was save
01/22 17:37:23: INFO >> "POST /api-token-auth/ HTTP/1.1" 200 262
01/22 17:38:12: INFO >> Token for user with email <BoundField value=pvpasha@meta.ua errors=None> was save
01/22 17:38:13: INFO >> "POST /api-token-auth/ HTTP/1.1" 200 262
01/22 17:38:18: INFO >> Token for user with email <BoundField value=pvpasha@meta.ua errors=None> was save
01/22 17:38:19: INFO >> "POST /api-token-auth/ HTTP/1.1" 200 262
01/22 17:38:20: INFO >> Token for user with email <BoundField value=pvpasha@meta.ua errors=None> was save
01/22 17:38:21: INFO >> "POST /api-token-auth/ HTTP/1.1" 200 262
01/22 17:39:45: INFO >> Token for user with email <BoundField value=pvpasha@meta.ua errors=None> was save
01/22 17:39:46: INFO >> "POST /api-token-auth/ HTTP/1.1" 200 262
01/22 17:39:47: INFO >> Token for user with email <BoundField value=pvpasha@meta.ua errors=None> was save
01/22 17:39:48: INFO >> "POST /api-token-auth/ HTTP/1.1" 200 262
01/22 17:40:55: INFO >> Token for user with email <BoundField value=pvpasha@meta.ua errors=None> was save
01/22 17:40:55: INFO >> "POST /api-token-auth/ HTTP/1.1" 200 262
01/22 17:40:58: INFO >> Token for user with email <BoundField value=pvpasha@meta.ua errors=None> was save
01/22 17:40:58: INFO >> "POST /api-token-auth/ HTTP/1.1" 200 262
01/22 17:48:39: INFO >> "OPTIONS /api-token-auth/ HTTP/1.1" 200 0
01/22 17:48:39: INFO >> Token for user with email <BoundField value=pvpasha@meta.ua errors=None> was save
01/22 17:48:40: INFO >> "POST /api-token-auth/ HTTP/1.1" 200 262
01/22 17:49:33: INFO >> Token for user with email <BoundField value=pvpasha@meta.ua errors=None> was save
01/22 17:49:34: INFO >> "POST /api-token-auth/ HTTP/1.1" 200 262
01/22 17:49:40: INFO >> Token for user with email <BoundField value=pvpasha@meta.ua errors=None> was save
01/22 17:49:40: INFO >> "POST /api-token-auth/ HTTP/1.1" 200 262
01/22 17:49:44: INFO >> Token for user with email <BoundField value=pvpasha@meta.ua errors=None> was save
01/22 17:49:44: INFO >> "POST /api-token-auth/ HTTP/1.1" 200 262
01/22 17:49:46: INFO >> Token for user with email <BoundField value=pvpasha@meta.ua errors=None> was save
01/22 17:49:47: INFO >> "POST /api-token-auth/ HTTP/1.1" 200 262
01/22 17:49:48: INFO >> Token for user with email <BoundField value=pvpasha@meta.ua errors=None> was save
01/22 17:49:49: INFO >> "POST /api-token-auth/ HTTP/1.1" 200 262
01/22 17:53:30: INFO >> Token for user with email <BoundField value=pvpasha@meta.ua errors=None> was save
01/22 17:53:30: INFO >> "POST /api-token-auth/ HTTP/1.1" 200 262
01/22 17:56:24: INFO >> Token for user with email <BoundField value=pvpasha@meta.ua errors=None> was save
01/22 17:56:25: INFO >> "POST /api-token-auth/ HTTP/1.1" 200 262
01/22 17:56:26: INFO >> Token for user with email <BoundField value=pvpasha@meta.ua errors=None> was save
01/22 17:56:27: INFO >> "POST /api-token-auth/ HTTP/1.1" 200 262
01/22 17:56:28: INFO >> Token for user with email <BoundField value=pvpasha@meta.ua errors=None> was save
01/22 17:56:29: INFO >> "POST /api-token-auth/ HTTP/1.1" 200 262
01/22 17:56:30: INFO >> Token for user with email <BoundField value=pvpasha@meta.ua errors=None> was save
01/22 17:56:31: INFO >> "POST /api-token-auth/ HTTP/1.1" 200 262
01/22 17:56:32: INFO >> Token for user with email <BoundField value=pvpasha@meta.ua errors=None> was save
01/22 17:56:33: INFO >> "POST /api-token-auth/ HTTP/1.1" 200 262
01/22 17:56:33: INFO >> Token for user with email <BoundField value=pvpasha@meta.ua errors=None> was save
01/22 17:56:34: INFO >> "POST /api-token-auth/ HTTP/1.1" 200 262
01/22 17:56:35: INFO >> Token for user with email <BoundField value=pvpasha@meta.ua errors=None> was save
01/22 17:56:36: INFO >> "POST /api-token-auth/ HTTP/1.1" 200 262
01/22 17:56:46: INFO >> Token for user with email <BoundField value=pvpasha@meta.ua errors=None> was save
01/22 17:56:47: INFO >> "POST /api-token-auth/ HTTP/1.1" 200 262
01/22 17:59:10: INFO >> "OPTIONS /api-token-auth/ HTTP/1.1" 200 0
01/22 17:59:10: INFO >> Token for user with email <BoundField value=pvpasha@meta.ua errors=None> was save
01/22 17:59:11: INFO >> "POST /api-token-auth/ HTTP/1.1" 200 262
01/22 17:59:14: INFO >> Token for user with email <BoundField value=pvpasha@meta.ua errors=None> was save
01/22 17:59:15: INFO >> "POST /api-token-auth/ HTTP/1.1" 200 262
01/22 17:59:16: INFO >> Token for user with email <BoundField value=pvpasha@meta.ua errors=None> was save
01/22 17:59:17: INFO >> "POST /api-token-auth/ HTTP/1.1" 200 262
01/22 17:59:17: INFO >> Token for user with email <BoundField value=pvpasha@meta.ua errors=None> was save
01/22 17:59:18: INFO >> "POST /api-token-auth/ HTTP/1.1" 200 262
01/22 17:59:18: INFO >> Token for user with email <BoundField value=pvpasha@meta.ua errors=None> was save
01/22 17:59:19: INFO >> "POST /api-token-auth/ HTTP/1.1" 200 262
01/22 17:59:18: INFO >> Token for user with email <BoundField value=pvpasha@meta.ua errors=None> was save
01/22 17:59:20: INFO >> "POST /api-token-auth/ HTTP/1.1" 200 262
01/22 17:59:18: INFO >> Token for user with email <BoundField value=pvpasha@meta.ua errors=None> was save
01/22 17:59:20: INFO >> "POST /api-token-auth/ HTTP/1.1" 200 262
01/22 18:00:21: INFO >> Token for user with email <BoundField value=pvpasha@meta.ua errors=None> was save
01/22 18:00:22: INFO >> "POST /api-token-auth/ HTTP/1.1" 200 262
01/22 18:00:22: INFO >> Token for user with email <BoundField value=pvpasha@meta.ua errors=None> was save
01/22 18:00:23: INFO >> "POST /api-token-auth/ HTTP/1.1" 200 262
01/22 18:00:25: INFO >> Token for user with email <BoundField value=pvpasha@meta.ua errors=None> was save
01/22 18:00:25: INFO >> "POST /api-token-auth/ HTTP/1.1" 200 262
01/22 18:00:26: INFO >> Token for user with email <BoundField value=pvpasha@meta.ua errors=None> was save
01/22 18:00:27: INFO >> "POST /api-token-auth/ HTTP/1.1" 200 262
01/22 18:02:44: INFO >> Token for user with email <BoundField value=pvpasha@meta.ua errors=None> was save
01/22 18:02:45: INFO >> "POST /api-token-auth/ HTTP/1.1" 200 262
01/22 18:03:18: INFO >> Token for user with email <BoundField value=pvpasha@meta.ua errors=None> was save
01/22 18:03:18: INFO >> "POST /api-token-auth/ HTTP/1.1" 200 262
01/22 20:58:59: INFO >> "OPTIONS /api-token-auth/ HTTP/1.1" 200 0
01/22 20:59:00: INFO >> Token for user with email <BoundField value=pvpasha@meta.ua errors=None> was save
01/22 20:59:00: INFO >> "POST /api-token-auth/ HTTP/1.1" 200 262
01/23 00:36:06: INFO >> "OPTIONS /api-token-auth/ HTTP/1.1" 200 0
01/23 00:36:07: INFO >> Token for user with email <BoundField value=pvpasha@meta.ua errors=None> was save
01/23 00:36:08: INFO >> "POST /api-token-auth/ HTTP/1.1" 200 262
01/23 00:36:42: INFO >> Token for user with email <BoundField value=pvpasha@meta.ua errors=None> was save
01/23 00:36:43: INFO >> "POST /api-token-auth/ HTTP/1.1" 200 262
01/23 00:36:45: INFO >> Token for user with email <BoundField value=pvpasha@meta.ua errors=None> was save
01/23 00:36:45: INFO >> "POST /api-token-auth/ HTTP/1.1" 200 262
01/23 00:37:00: INFO >> Token for user with email <BoundField value=pvpasha@meta.ua errors=None> was save
01/23 00:37:01: INFO >> "POST /api-token-auth/ HTTP/1.1" 200 262
